Workbook
Name Slicer_Campaign_Name: #N/A
Name Slicer_Country: #N/A
Name Slicer_Product_Name: #N/A
Name Slicer_Sales_Stage: #N/A

Sheet Customers
A1: Customer_ID | B1: First_Name | C1: Last_Name | D1: Customer_Type | E1: Country | F1: Email | G1: Phone | H1: Created_Date | I1: Data_Quality_Status
A2: C0001 | B2: John | C2: Smith | D2: Homeowner | E2: France | F2: daniel.smith1@example.com | G2: +33 350 328 3286 | H2: 46030 | I2: Valid
A3: C0002 | B3: William | C3: Patel | D3: Commercial | E3: UK | F3: william.patel2@example.com | G3: +44 617 716 1434 | H3: 46137 | I3: Valid
A4: C0003 | B4: Florence | C4: Wright | D4: Installer | E4: UK | F4: florence.wright3@example.com | G4: +44 877 925 3615 | H4: 46268 | I4: Valid
A5: C0004 | B5: Olivia | C5: Taylor | D5: Architect | E5: UK | F5: olivia.taylor4@example.com | G5: +44 489 199 6881 | H5: 46160 | I5: Valid
A6: C0005 | B6: Daniel | C6: Edwards | D6: Commercial | E6: UK | F6: daniel.edwards5@example.com | G6: +44 665 400 6925 | H6: 46220 | I6: Valid
A7: C0006 | B7: Noah | C7: Wilson | D7: Architect | E7: UK | F7: noah.wilson6@example.com | G7: +44 987 203 7227 | H7: 46113 | I7: Valid
A8: C0007 | B8: Jacob | C8: Wright | D8: Commercial | E8: UK | F8: jacob.wright7@example.com | G8: +44 723 750 3803 | H8: 46092 | I8: Valid
A9: C0008 | B9: Charlotte | C9: Robinson | D9: Dealer | E9: France | G9: +33 963 886 1916 | H9: 46039 | I9: Review - Missing Email
A10: C0009 | B10: Jacob | C10: Jackson | D10: Installer | E10: France | F10: jacob.jackson9@example.com | G10: +33 317 771 9179 | H10: 46086 | I10: Valid
A11: C0010 | B11: Charlotte | C11: Clarke | D11: Commercial | E11: UK | F11: charlotte.clarke10@example.com | G11: +44 864 698 8019 | H11: 46153 | I11: Valid
A12: C0011 | B12: Lily | C12: Wilson | D12: Dealer | E12: UK | F12: lily.wilson11@example.com | G12: +44 981 212 3504 | H12: 46120 | I12: Valid
A13: C0012 | B13: Ruby | C13: Green | D13: Homeowner | E13: Netherlands | F13: ruby.green12@example.com | G13: +31 357 666 1188 | H13: 46098 | I13: Valid
A14: C0013 | B14: Isabella | C14: Davies | D14: Commercial | E14: Ireland | F14: isabella.davies13@example.com | G14: +353 103 839 5315 | H14: 46238 | I14: Valid
A15: C0014 | B15: Freya | C15: Wood | D15: Commercial | E15: UK | F15: freya.wood14@example.com | G15: +44 256 482 3646 | H15: 46027 | I15: Valid
A16: C0015 | B16: Daniel | C16: White | D16: Commercial | E16: France | F16: daniel.white15@example.com | G16: +33 345 159 4946 | H16: 46273 | I16: Valid
A17: C0016 | B17: Alice | C17: Johnson | D17: Architect | E17: UK | F17: alice.johnson16@example.com | G17: +44 775 586 3705 | H17: 46260 | I17: Valid
A18: C0017 | B18: Alice | C18: Patel | D18: Installer | E18: France | F18: alice.patel17@example.com | G18: +33 508 787 7118 | H18: 46080 | I18: Valid
A19: C0018 | B19: Robert | C19: Walker | D19: Commercial | E19: UK | F19: robert.walker18@example.com | G19: +44 702 667 4770 | H19: 46081 | I19: Valid
A20: C0019 | B20: Robert | C20: Brown | D20: Architect | E20: France | F20: robert.brown19@example.com | G20: +33 172 626 4899 | H20: 46208 | I20: Valid
A21: C0020 | B21: Evie | C21: Jackson | D21: Installer | E21: Spain | F21: evie.jackson20@example.com | G21: +34 348 903 8749 | H21: 46113 | I21: Valid
... A50: C0049 | B50: Freya | C50: Hughes | D50: Installer | E50: Belgium | F50: freya.hughes49@example.com | G50: +32 556 262 8777 | H50: 46183 | I50: Valid
A51: C0050 | B51: Oscar | C51: Wright | D51: Dealer | E51: Ireland | F51: oscar.wright50@example.com | H51: 46058 | I51: Review - Missing Phone
A52: C0051 | B52: George | C52: Robinson | D52: Homeowner | E52: Germany | F52: george.robinson51@example.com | G52: +49 810 256 4505 | H52: 46129 | I52: Valid
A53: C0052 | B53: Michael | C53: Patel | D53: Commercial | E53: Ireland | F53: michael.patel52@example.com | G53: +353 498 888 1320 | H53: 46099 | I53: Valid
A54: C0053 | B54: Sophia | C54: Hughes | D54: Commercial | E54: Netherlands | F54: sophia.hughes53@example.com | G54: +31 865 852 9947 | H54: 46134 | I54: Valid
A55: C0054 | B55: Lily | C55: Smith | D55: Dealer | E55: Germany | F55: lily.smith54@example.com | G55: +49 444 784 7624 | H55: 46255 | I55: Valid
A56: C0055 | B56: Isla | C56: Jackson | D56: Installer | E56: Belgium | F56: isla.jackson55@example.com | G56: +32 778 127 2375 | H56: 46089 | I56: Valid
A57: C0056 | B57: Sophia | C57: Walker | D57: Installer | E57: UK | F57: sophia.walker56@example.com | G57: +44 565 434 6529 | H57: 46143 | I57: Valid
A58: C0057 | B58: James | C58: Clarke | D58: Homeowner | E58: UK | F58: james.clarke57@example.com | G58: +44 458 329 2124 | H58: 46182 | I58: Valid
A59: C0058 | B59: George | C59: Robinson | D59: Commercial | E59: UK | F59: george.robinson58@example.com | G59: +44 584 785 2874 | H59: 46065 | I59: Valid
A60: C0059 | B60: Ruby | C60: Wood | D60: Architect | E60: UK | F60: ruby.wood59@example.com | G60: +44 896 938 3683 | H60: 46170 | I60: Valid
A61: C0060 | B61: Sophia | C61: Edwards | D61: Homeowner | E61: UK | F61: sophia.edwards60@example.com | G61: +44 177 706 4978 | H61: 46111 | I61: Valid
A62: C0061 | B62: Alice | C62: Hughes | D62: Homeowner | E62: Germany | F62: alice.hughes61@example.com | G62: +49 170 618 6590 | H62: 46268 | I62: Valid
A63: C0062 | B63: Emily | C63: Green | D63: Architect | E63: UK | F63: emily.green62@example.com | G63: +44 545 280 9548 | H63: 46134 | I63: Valid
... A119: C0118 | B119: Olivia | C119: Green | D119: Architect | E119: Germany | F119: olivia.green118@example.com | G119: +49 525 847 2557 | H119: 46267 | I119: Valid
A120: C0119 | C120: Hall | D120: Homeowner | E120: UK | F120: george.hall119@example.com | G120: +44 193 951 2398 | H120: 46165 | I120: Review - Missing Name
A121: C0120 | B121: Michael | C121: Jackson | D121: Installer | E121: Belgium | F121: michael.jackson120@example.com | G121: +32 675 437 3002 | H121: 46176 | I121: Valid
A122: C0121 | B122: Theo | C122: White | D122: Dealer | E122: UK | F122: theo.white121@example.com | G122: +44 691 619 4485 | H122: 46239 | I122: Valid
A123: C0122 | B123: Charlotte | C123: White | D123: Installer | E123: UK | F123: charlotte.white122@example.com | G123: +44 880 385 4705 | H123: 46178 | I123: Valid
...

Sheet Sheet2
A1: Data returned for Total Leads, Instagram (First 1000 rows).
A3: Leads[Lead_ID] | B3: Leads[Customer_ID] | C3: Leads[Lead_Date] | D3: Leads[Lead_Source] | E3: Leads[Product_ID] | F3: Leads[Product_Name] | G3: Leads[Sales_Stage] | H3: Leads[Lead_Score] | I3: Leads[Estimated_Value] | J3: Leads[Assigned_To] | K3: Leads[Next_Follow_Up] | L3: Leads[Campaign_ID] | M3: Leads[Column1]
A4: L0143 | B4: C0143 | C4: 46098 | D4: Instagram | E4: P002 | F4: EC645 | G4: Qualified | H4: 40 | I4: 7000 | J4: Sarah | K4: 46105 | L4: CAM010 | M4: 1
A5: L0101 | B5: C0101 | C5: 46158 | D5: Instagram | E5: P002 | F5: EC645 | G5: Lost | H5: 0 | I5: 0 | J5: James | K5: 46165 | L5: CAM010 | M5: 1
A6: L0072 | B6: C0072 | C6: 46178 | D6: Instagram | E6: P001 | F6: EC580 | G6: Lost | H6: 0 | I6: 0 | J6: Emma | K6: 46185 | L6: CAM010 | M6: 1
A7: L0023 | B7: C0023 | C7: 46146 | D7: Instagram | E7: P002 | F7: EC645 | G7: Negotiation | H7: 85 | I7: 10000 | J7: Emma | K7: 46153 | L7: CAM010 | M7: 1
A8: L0020 | B8: C0020 | C8: 46113 | D8: Instagram | E8: P001 | F8: EC580 | G8: Contacted | H8: 20 | I8: 5000 | J8: Emma | K8: 46120 | L8: CAM010 | M8: 1
A9: L0018 | B9: C0018 | C9: 46081 | D9: Instagram | E9: P001 | F9: EC580 | G9: Contacted | H9: 20 | I9: 5000 | J9: Sarah | K9: 46088 | L9: CAM010 | M9: 1
A10: L0007 | B10: C0007 | C10: 46092 | D10: Instagram | E10: P002 | F10: EC645 | G10: Won | H10: 100 | I10: 12000 | J10: Emma | K10: 46099 | L10: CAM010 | M10: 1
A11: L0005 | B11: C0005 | C11: 46220 | D11: Instagram | E11: P001 | F11: EC580 | G11: New Lead | H11: 10 | I11: 4000 | J11: David | K11: 46227 | L11: CAM010 | M11: 1

Sheet Sheet3
A1: Data returned for Total Activities, Email, All - All - All (First 1000 rows).
A3: Leads[Lead_ID] | B3: Leads[Customer_ID] | C3: Leads[Lead_Date] | D3: Leads[Lead_Source] | E3: Leads[Product_ID] | F3: Leads[Product_Name] | G3: Leads[Sales_Stage] | H3: Leads[Lead_Score] | I3: Leads[Estimated_Value] | J3: Leads[Assigned_To] | K3: Leads[Next_Follow_Up] | L3: Leads[Campaign_ID] | M3: Leads[Column1]
A4: L0001 | B4: C0001 | C4: 46030 | D4: Phone | E4: P001 | F4: EC580 | G4: Negotiation | H4: 85 | I4: 10000 | J4: Sarah | K4: 46037 | L4: CAM012 | M4: 1
A5: L0005 | B5: C0005 | C5: 46220 | D5: Instagram | E5: P001 | F5: EC580 | G5: New Lead | H5: 10 | I5: 4000 | J5: David | K5: 46227 | L5: CAM010 | M5: 1
A6: L0002 | B6: C0002 | C6: 46137 | D6: Instagram | E6: P005 | F6: E850 | G6: Negotiation | H6: 85 | I6: 10000 | J6: David | K6: 46144 | L6: CAM010 | M6: 1
A7: L0003 | B7: C0003 | C7: 46268 | D7: Referral | E7: P003 | F7: EC678 | G7: Qualified | H7: 40 | I7: 7000 | J7: David | K7: 46275 | L7: CAM008 | M7: 1
A8: L0004 | B8: C0004 | C8: 46160 | D8: Organic Search | E8: P003 | F8: EC678 | G8: New Lead | H8: 10 | I8: 4000 | J8: Emma | K8: 46167 | L8: CAM009 | M8: 1
A9: L0006 | B9: C0006 | C9: 46113 | D9: Email | E9: P003 | F9: EC678 | G9: Qualified | H9: 40 | I9: 7000 | J9: James | K9: 46120 | L9: CAM006 | M9: 1
A10: L0007 | B10: C0007 | C10: 46092 | D10: Instagram | E10: P002 | F10: EC645 | G10: Won | H10: 100 | I10: 12000 | J10: Emma | K10: 46099 | L10: CAM010 | M10: 1
A11: L0008 | B11: C0008 | C11: 46039 | D11: Website | E11: P003 | F11: EC678 | G11: Negotiation | H11: 85 | I11: 10000 | J11: James | K11: 46046 | L11: CAM001 | M11: 1
A12: L0009 | B12: C0009 | C12: 46086 | D12: Email | E12: P002 | F12: EC645 | G12: Site Survey | H12: 65 | I12: 8000 | J12: David | K12: 46093 | L12: CAM006 | M12: 1
A13: L0010 | B13: C0010 | C13: 46153 | D13: Dealer | E13: P003 | F13: EC678 | G13: Information Pack Sent | H13: 50 | I13: 6000 | J13: David | K13: 46160 | L13: CAM005 | M13: 1
A14: L0011 | B14: C0011 | C14: 46120 | D14: Dealer | E14: P005 | F14: E850 | G14: Contacted | H14: 20 | I14: 5000 | J14: Emma | K14: 46127 | L14: CAM005 | M14: 1
A15: L0012 | B15: C0012 | C15: 46098 | D15: Phone | E15: P003 | F15: EC678 | G15: Proposal | H15: 75 | I15: 9000 | J15: Sarah | K15: 46105 | L15: CAM012 | M15: 1
... A153: L0150 | B153: C0150 | C153: 46058 | D153: Referral | E153: P001 | F153: EC580 | G153: Proposal | H153: 75 | I153: 9000 | J153: David | K153: 46065 | L153: CAM008 | M153: 1

Sheet Sheet4
A1: Data returned for Expected Value, Won, All - All - All - All (First 1000 rows).
A3: Opportunities[Opportunity_ID] | B3: Opportunities[Lead_ID] | C3: Opportunities[Customer_ID] | D3: Opportunities[Product_ID] | E3: Opportunities[Product_Name] | F3: Opportunities[Opportunity_Name] | G3: Opportunities[Pipeline_Stage] | H3: Opportunities[Amount] | I3: Opportunities[Probability] | J3: Opportunities[Expected_Value] | K3: Opportunities[Expected_Close_Date] | L3: Opportunities[Owner] | M3: Opportunities[Lead_Date]
A4: O0007 | B4: L0007 | C4: C0007 | D4: P002 | E4: EC645 | F4: EC645 Opportunity | G4: Won | H4: 12000 | I4: 100 | J4: 12000 | K4: 46099 | L4: Emma | M4: 46092
A5: O0015 | B5: L0015 | C5: C0015 | D5: P001 | E5: EC580 | F5: EC580 Opportunity | G5: Won | H5: 12000 | I5: 100 | J5: 12000 | K5: 46280 | L5: Sarah | M5: 46273
A6: O0062 | B6: L0062 | C6: C0062 | D6: P005 | E6: E850 | F6: E850 Opportunity | G6: Won | H6: 12000 | I6: 100 | J6: 12000 | K6: 46141 | L6: Emma | M6: 46134
A7: O0063 | B7: L0063 | C7: C0063 | D7: P002 | E7: EC645 | F7: EC645 Opportunity | G7: Won | H7: 12000 | I7: 100 | J7: 12000 | K7: 46116 | L7: Emma | M7: 46109
A8: O0065 | B8: L0065 | C8: C0065 | D8: P003 | E8: EC678 | F8: EC678 Opportunity | G8: Won | H8: 12000 | I8: 100 | J8: 12000 | K8: 46144 | L8: Emma | M8: 46137
A9: O0066 | B9: L0066 | C9: C0066 | D9: P003 | E9: EC678 | F9: EC678 Opportunity | G9: Won | H9: 12000 | I9: 100 | J9: 12000 | K9: 46138 | L9: James | M9: 46131
A10: O0071 | B10: L0071 | C10: C0071 | D10: P004 | E10: EC730 | F10: EC730 Opportunity | G10: Won | H10: 12000 | I10: 100 | J10: 12000 | K10: 46177 | L10: Sarah | M10: 46170
A11: O0077 | B11: L0077 | C11: C0077 | D11: P003 | E11: EC678 | F11: EC678 Opportunity | G11: Won | H11: 12000 | I11: 100 | J11: 12000 | K11: 46149 | L11: Sarah | M11: 46142
A12: O0080 | B12: L0080 | C12: C0080 | D12: P004 | E12: EC730 | F12: EC730 Opportunity | G12: Won | H12: 12000 | I12: 100 | J12: 12000 | K12: 46150 | L12: Sarah | M12: 46143
A13: O0081 | B13: L0081 | C13: C0081 | D13: P004 | E13: EC730 | F13: EC730 Opportunity | G13: Won | H13: 12000 | I13: 100 | J13: 12000 | K13: 46199 | L13: James | M13: 46192
A14: O0083 | B14: L0083 | C14: C0083 | D14: P004 | E14: EC730 | F14: EC730 Opportunity | G14: Won | H14: 12000 | I14: 100 | J14: 12000 | K14: 46082 | L14: Sarah | M14: 46075
A15: O0088 | B15: L0088 | C15: C0088 | D15: P005 | E15: E850 | F15: E850 Opportunity | G15: Won | H15: 12000 | I15: 100 | J15: 12000 | K15: 46115 | L15: James | M15: 46108
... A24: O0146 | B24: L0146 | C24: C0146 | D24: P005 | E24: E850 | F24: E850 Opportunity | G24: Won | H24: 12000 | I24: 100 | J24: 12000 | K24: 46226 | L24: Emma | M24: 46219

Sheet Sheet7
A1: Data returned for Expected Pipeline Value, UK - All - All - All (First 1000 rows).
A3: Leads[Lead_ID] | B3: Leads[Customer_ID] | C3: Leads[Lead_Date] | D3: Leads[Lead_Source] | E3: Leads[Product_ID] | F3: Leads[Product_Name] | G3: Leads[Sales_Stage] | H3: Leads[Lead_Score] | I3: Leads[Estimated_Value] | J3: Leads[Assigned_To] | K3: Leads[Next_Follow_Up] | L3: Leads[Campaign_ID] | M3: Leads[Column1]
A4: L0005 | B4: C0005 | C4: 46220 | D4: Instagram | E4: P001 | F4: EC580 | G4: New Lead | H4: 10 | I4: 4000 | J4: David | K4: 46227 | L4: CAM010 | M4: 1
A5: L0002 | B5: C0002 | C5: 46137 | D5: Instagram | E5: P005 | F5: E850 | G5: Negotiation | H5: 85 | I5: 10000 | J5: David | K5: 46144 | L5: CAM010 | M5: 1
A6: L0003 | B6: C0003 | C6: 46268 | D6: Referral | E6: P003 | F6: EC678 | G6: Qualified | H6: 40 | I6: 7000 | J6: David | K6: 46275 | L6: CAM008 | M6: 1
A7: L0004 | B7: C0004 | C7: 46160 | D7: Organic Search | E7: P003 | F7: EC678 | G7: New Lead | H7: 10 | I7: 4000 | J7: Emma | K7: 46167 | L7: CAM009 | M7: 1
A8: L0006 | B8: C0006 | C8: 46113 | D8: Email | E8: P003 | F8: EC678 | G8: Qualified | H8: 40 | I8: 7000 | J8: James | K8: 46120 | L8: CAM006 | M8: 1
A9: L0007 | B9: C0007 | C9: 46092 | D9: Instagram | E9: P002 | F9: EC645 | G9: Won | H9: 100 | I9: 12000 | J9: Emma | K9: 46099 | L9: CAM010 | M9: 1
A10: L0010 | B10: C0010 | C10: 46153 | D10: Dealer | E10: P003 | F10: EC678 | G10: Information Pack Sent | H10: 50 | I10: 6000 | J10: David | K10: 46160 | L10: CAM005 | M10: 1
A11: L0011 | B11: C0011 | C11: 46120 | D11: Dealer | E11: P005 | F11: E850 | G11: Contacted | H11: 20 | I11: 5000 | J11: Emma | K11: 46127 | L11: CAM005 | M11: 1
A12: L0014 | B12: C0014 | C12: 46027 | D12: Phone | E12: P001 | F12: EC580 | G12: Proposal | H12: 75 | I12: 9000 | J12: Emma | K12: 46034 | L12: CAM012 | M12: 1
A13: L0016 | B13: C0016 | C13: 46260 | D13: Phone | E13: P005 | F13: E850 | G13: Negotiation | H13: 85 | I13: 10000 | J13: David | K13: 46267 | L13: CAM012 | M13: 1
A14: L0018 | B14: C0018 | C14: 46081 | D14: Instagram | E14: P001 | F14: EC580 | G14: Contacted | H14: 20 | I14: 5000 | J14: Sarah | K14: 46088 | L14: CAM010 | M14: 1
A15: L0022 | B15: C0022 | C15: 46136 | D15: Exhibition | E15: P004 | F15: EC730 | G15: Information Pack Sent | H15: 50 | I15: 6000 | J15: Sarah | K15: 46143 | L15: CAM004 | M15: 1
... A82: L0145 | B82: C0145 | C82: 46215 | D82: Referral | E82: P002 | F82: EC645 | G82: Won | H82: 100 | I82: 12000 | J82: James | K82: 46222 | L82: CAM008 | M82: 1

Sheet Pivot_Analysis
B3: Row Labels | C3: Total Leads | E3: Row Labels | F3: Total Leads | H3: Row Labels | I3: Total Leads | L3: Row Labels | M3: Won Leads | N3: Total Leads
B4: Proposal | C4: 11 | E4: Google | F4: 9 | H4: EC730 | I4: 33 | L4: Email Product | M4: 3 | N4: 14
B5: Lost | C5: 14 | E5: Facebook | F5: 9 | H5: E850 | I5: 33 | L5: UK Home Show | M5: 1 | N5: 16
B6: Information Pack Sent | C6: 15 | E6: Website | F6: 13 | H6: EC678 | I6: 31 | L6: Customer Referral Campaign | M6: 4 | N6: 19
B7: New Lead | C7: 16 | E7: Dealer | F7: 14 | H7: EC645 | I7: 27 | L7: Dealer Referral Programme | N7: 14
B8: Qualified | C8: 17 | E8: Email | F8: 14 | H8: EC580 | I8: 26 | L8: Facebook Product Campaign | M8: 1 | N8: 9
B9: Negotiation | C9: 17 | E9: Phone | F9: 15 | H9: Grand Total | I9: 150 | L9: Google Search Campaign | M9: 3 | N9: 9
B10: Contacted | C10: 19 | E10: Exhibition | F10: 16 | L10: Instagram Product Campaign | M10: 2 | N10: 21
B11: Site Survey | C11: 20 | E11: Referral | F11: 19 | L11: Organic Search Campaign | M11: 5 | N11: 20
B12: Won | C12: 21 | E12: Organic Search | F12: 20 | L12: Phone Enquiry Campaign | M12: 1 | N12: 15
B13: Grand Total | C13: 150 | E13: Instagram | F13: 21 | L13: Website Enquiry Campaign | M13: 1 | N13: 13
E14: Grand Total | F14: 150 | L14: Grand Total | M14: 21 | N14: 150
B17: Row Labels | C17: Expected Value | D17: Opportunity Amount | F17: Row Labels | G17: Total Activities | I17: Total Leads | J17: Qualified Leads | K17: Won Leads | L17: Conversion Rate | M17: Total Pipeline Value | N17: Expected Pipeline Value | O17: Total Activities
B18: Won | C18: 252000 | D18: 252000 | F18: Email | G18: 165 | I18: 150 | J18: 17 | K18: 21 | L18: 0.14 | M18: 1049000 | N18: 692750 | O18: 507
B19: Negotiation | C19: 144500 | D19: 170000 | F19: Phone Call | G19: 134
B20: Site Survey | C20: 104000 | D20: 160000 | F20: Follow-up | G20: 101
B21: Qualified | C21: 47600 | D21: 119000 | F21: Site Survey | G21: 69
B22: Proposal | C22: 74250 | D22: 99000 | F22: Meeting | G22: 38
B23: Contacted | C23: 19000 | D23: 95000 | F23: Grand Total | G23: 507
B24: Information Pack Sent | C24: 45000 | D24: 90000
B25: New Lead | C25: 6400 | D25: 64000
B26: Lost | C26: 0 | D26: 0
B27: Grand Total | C27: 692750 | D27: 1049000
B30: Row Labels | C30: Total Leads
B31: Architect | C31: 38
B32: Homeowner | C32: 36
B33: Installer | C33: 28
B34: Commercial | C34: 24
B35: Dealer | C35: 24
B36: Grand Total | C36: 150

Sheet DashBoard 
A1: #VALUE! | C1: ECCO STOVE | I1: ECCO STOVE — CRM & SALES DASHBOARD
A6: FILTER & CONTEXT | I6: Total Leads | M6: Qualified Leads | R6: Won Leads | W6: Conversion Rate | AB6: Total Pipeline
I7: =GETPIVOTDATA("[Measures].[Total Leads]",Pivot_Analysis!$I$17) -> 150 | M7: =GETPIVOTDATA("[Measures].[Qualified Leads]",Pivot_Analysis!$I$17) -> 17 | R7: =GETPIVOTDATA("[Measures].[Won Leads]",Pivot_Analysis!$I$17) -> 21 | W7: =GETPIVOTDATA("[Measures].[Conversion Rate]",Pivot_Analysis!$I$17) -> 0.14 | AB7: =GETPIVOTDATA("[Measures].[Total Pipeline Value]",Pivot_Analysis!$I$17) -> 1049000
A8: Groups
H10: LEAD & CAMPAIGN INSIGHTS
H26: PIPELINE ANALYSIS
A28: Key Business Insights :
B29: {=IFERROR( _xlfn.LET( _xlpm.Names,Pivot_Analysis!$H$4:$H$100, _xlpm.Values,Pivot_Analysis!$I$4:$I$100, _xlpm.Valid,(_xlpm.Names<>"")*(_xlpm.Names<>"Grand Total"), _xlpm.Top,MAX(_xlfn._xlws.FILTER(_xlpm.Values,_xlpm.Valid)), "Top products: "&_xlfn.TEXTJOIN(", ",TRUE,_xlfn._xlws.FILTER(_xlpm.Names,_xlpm.Valid*(_xlpm.Values=_xlpm.Top)))&", with "&_xlpm.Top&" leads." ), "No product data available for the current filters." )} -> Top products: EC730, E850, with 33 leads.
B31: ="Total pipeline value : "&TEXT(AB7,"£#,##0")&"." -> Total pipeline value : £1,049,000.
B33: ="Expected pipeline value : "&TEXT(Pivot_Analysis!N18,"£#,##0")&"." -> Expected pipeline value : £692,750.
B35: {=IFERROR( "Top lead source : "&INDEX(_xlfn._xlws.FILTER(Pivot_Analysis!$E$4:$E$100,(Pivot_Analysis!$E$4:$E$100<>"Grand Total")*(Pivot_Analysis!$E$4:$E$100<>"")),MATCH(MAX(_xlfn._xlws.FILTER(Pivot_Analysis!$F$4:$F$100,(Pivot_Analysis!$E$4:$E$100<>"Grand Total")*(Pivot_Analysis!$E$4:$E$100<>""))),_xlfn._xlws.FILTER(Pivot_Analysis!$F$4:$F$100,(Pivot_Analysis!$E$4:$E$100<>"Grand Total")*(Pivot_Analysis!$E$4:$E$100<>"")),0))&", generating "&MAX(_xlfn._xlws.FILTER(Pivot_Analysis!$F$4:$F$100,(Pivot_Analysis!$E$4:$E$100<>"Grand Total")*(Pivot_Analysis!$E$4:$E$100<>"")))&" leads.", "No lead source data available for the current filters." )} -> Top lead source : Instagram, generating 21 leads.
B37: =IFERROR("Conversion rate : "&TEXT(W7,"0%")&", with "&R7&" won leads out of "&I7&" total leads.","Conversion rate data is currently unavailable.") -> Conversion rate : 14%, with 21 won leads out of 150 total leads.

Sheet Leads
A1: Lead_ID | B1: Customer_ID | C1: Lead_Date | D1: Lead_Source | E1: Product_ID | F1: Product_Name | G1: Sales_Stage | H1: Lead_Score | I1: Estimated_Value | J1: Assigned_To | K1: Next_Follow_Up | L1: Campaign_ID | M1: Column1
A2: L0001 | B2: C0001 | C2: 46030 | D2: Phone | E2: P001 | F2: EC580 | G2: Negotiation | H2: 85 | I2: 10000 | J2: Sarah | K2: 46037 | L2: CAM012 | M2: =COUNTIF(B:B,B2) -> 1
A3: L0005 | B3: C0005 | C3: 46220 | D3: Instagram | E3: P001 | F3: EC580 | G3: New Lead | H3: 10 | I3: 4000 | J3: David | K3: 46227 | L3: CAM010 | M3: =COUNTIF(B:B,B3) -> 1
A4: L0002 | B4: C0002 | C4: 46137 | D4: Instagram | E4: P005 | F4: E850 | G4: Negotiation | H4: 85 | I4: 10000 | J4: David | K4: 46144 | L4: CAM010 | M4: =COUNTIF(B:B,B4) -> 1
A5: L0003 | B5: C0003 | C5: 46268 | D5: Referral | E5: P003 | F5: EC678 | G5: Qualified | H5: 40 | I5: 7000 | J5: David | K5: 46275 | L5: CAM008 | M5: =COUNTIF(B:B,B5) -> 1
A6: L0004 | B6: C0004 | C6: 46160 | D6: Organic Search | E6: P003 | F6: EC678 | G6: New Lead | H6: 10 | I6: 4000 | J6: Emma | K6: 46167 | L6: CAM009 | M6: =COUNTIF(B:B,B6) -> 1
A7: L0006 | B7: C0006 | C7: 46113 | D7: Email | E7: P003 | F7: EC678 | G7: Qualified | H7: 40 | I7: 7000 | J7: James | K7: 46120 | L7: CAM006 | M7: =COUNTIF(B:B,B7) -> 1
A8: L0007 | B8: C0007 | C8: 46092 | D8: Instagram | E8: P002 | F8: EC645 | G8: Won | H8: 100 | I8: 12000 | J8: Emma | K8: 46099 | L8: CAM010 | M8: =COUNTIF(B:B,B8) -> 1
A9: L0008 | B9: C0008 | C9: 46039 | D9: Website | E9: P003 | F9: EC678 | G9: Negotiation | H9: 85 | I9: 10000 | J9: James | K9: 46046 | L9: CAM001 | M9: =COUNTIF(B:B,B9) -> 1
A10: L0009 | B10: C0009 | C10: 46086 | D10: Email | E10: P002 | F10: EC645 | G10: Site Survey | H10: 65 | I10: 8000 | J10: David | K10: 46093 | L10: CAM006 | M10: =COUNTIF(B:B,B10) -> 1
A11: L0010 | B11: C0010 | C11: 46153 | D11: Dealer | E11: P003 | F11: EC678 | G11: Information Pack Sent | H11: 50 | I11: 6000 | J11: David | K11: 46160 | L11: CAM005 | M11: =COUNTIF(B:B,B11) -> 1
A12: L0011 | B12: C0011 | C12: 46120 | D12: Dealer | E12: P005 | F12: E850 | G12: Contacted | H12: 20 | I12: 5000 | J12: Emma | K12: 46127 | L12: CAM005 | M12: =COUNTIF(B:B,B12) -> 1
A13: L0012 | B13: C0012 | C13: 46098 | D13: Phone | E13: P003 | F13: EC678 | G13: Proposal | H13: 75 | I13: 9000 | J13: Sarah | K13: 46105 | L13: CAM012 | M13: =COUNTIF(B:B,B13) -> 1
... A151: L0150 | B151: C0150 | C151: 46058 | D151: Referral | E151: P001 | F151: EC580 | G151: Proposal | H151: 75 | I151: 9000 | J151: David | K151: 46065 | L151: CAM008 | M151: =COUNTIF(B:B,B151) -> 1

Sheet Products 
A1: Product_ID | B1: Product_Name | C1: Brand | D1: Category
A2: P001 | B2: EC580 | C2: Ecco Stove | D2: Heating System
A3: P002 | B3: EC645 | C3: Ecco Stove | D3: Heating System
A4: P003 | B4: EC678 | C4: Ecco Stove | D4: Heating System
A5: P004 | B5: EC730 | C5: Ecco Stove | D5: Heating System
A6: P005 | B6: E850 | C6: Ecco Stove | D6: Heating System

Sheet Activities
A1: Next_Action_Date | B1: Activity_ID | C1: Customer_ID | D1: Lead_ID | E1: Activity_Date | F1: Activity_Type | G1: Subject | H1: Outcome | I1: Next_Action | J1: Assigned_To
A2: 46033 | B2: L0001-A01 | C2: C0001 | D2: L0001 | E2: 46030 | F2: Email | G2: Product enquiry and information | H2: Information sent | I2: Phone Call | J2: Sarah
A3: 46036 | B3: L0001-A02 | C3: C0001 | D3: L0001 | E3: 46033 | F3: Phone Call | G3: Customer follow-up call | H3: Customer contacted | I3: Follow-up | J3: Sarah
A4: 46039 | B4: L0001-A03 | C4: C0001 | D4: L0001 | E4: 46036 | F4: Follow-up | G4: Follow-up on customer interest | H4: Customer interest confirmed | I4: Review Opportunity | J4: Sarah
A5: 46042 | B5: L0001-A04 | C5: C0001 | D5: L0001 | E5: 46039 | F5: Site Survey | G5: Property and installation assessment | H5: Site assessment completed | I5: Prepare Proposal | J5: Sarah
A6: 46045 | B6: L0001-A05 | C6: C0001 | D6: L0001 | E6: 46042 | F6: Meeting | G6: Customer meeting | H6: Discussion completed | I6: Follow-up | J6: Sarah
A7: 46223 | B7: L0005-A01 | C7: C0005 | D7: L0005 | E7: 46220 | F7: Email | G7: Product enquiry and information | H7: Information sent | I7: Phone Call | J7: David
A8: 46140 | B8: L0002-A01 | C8: C0002 | D8: L0002 | E8: 46137 | F8: Email | G8: Product enquiry and information | H8: Information sent | I8: Phone Call | J8: David
A9: 46143 | B9: L0002-A02 | C9: C0002 | D9: L0002 | E9: 46140 | F9: Phone Call | G9: Customer follow-up call | H9: Customer contacted | I9: Follow-up | J9: David
A10: 46146 | B10: L0002-A03 | C10: C0002 | D10: L0002 | E10: 46143 | F10: Follow-up | G10: Follow-up on customer interest | H10: Customer interest confirmed | I10: Review Opportunity | J10: David
A11: 46149 | B11: L0002-A04 | C11: C0002 | D11: L0002 | E11: 46146 | F11: Site Survey | G11: Property and installation assessment | H11: Site assessment completed | I11: Prepare Proposal | J11: David
A12: 46152 | B12: L0002-A05 | C12: C0002 | D12: L0002 | E12: 46149 | F12: Meeting | G12: Customer meeting | H12: Discussion completed | I12: Follow-up | J12: David
A13: 46271 | B13: L0003-A01 | C13: C0003 | D13: L0003 | E13: 46268 | F13: Email | G13: Product enquiry and information | H13: Information sent | I13: Phone Call | J13: David
... A508: 46070 | B508: L0150-A04 | C508: C0150 | D508: L0150 | E508: 46067 | F508: Site Survey | G508: Property and installation assessment | H508: Site assessment completed | I508: Prepare Proposal | J508: David

Sheet Marketing_Campaigns
A1: Campaign_ID | B1: Campaign_Name | C1: Channel | D1: Campaign_Type | E1: Start_Date | F1: End_Date | G1: Budget | H1: Campaign_Duration_Days | I1: Campaign_Status
A2: CAM001 | B2: Website Enquiry Campaign | C2: Website | D2: Organic | E2: 46174 | F2: 46203 | G2: 500 | H2: 30 | I2: Completed
A3: CAM002 | B3: Google Search Campaign | C3: Google | D3: Paid Search | E3: 46174 | F3: 46203 | G3: 1500 | H3: 30 | I3: Completed
A4: CAM003 | B4: Social Media Awareness | C4: Social Media | D4: Paid Social | E4: 46178 | F4: 46208 | G4: 1200 | H4: 31 | I4: Completed
A5: CAM004 | B5: UK Home Show | C5: Exhibition | D5: Event | E5: 46188 | F5: 46190 | G5: 3000 | H5: 3 | I5: Completed
A6: CAM005 | B6: Dealer Referral Programme | C6: Dealer | D6: Referral | E6: 46174 | F6: 46265 | G6: 800 | H6: 92 | I6: Completed
A7: CAM006 | B7: Email Product Promotion | C7: Email | D7: Email Marketing | E7: 46204 | F7: 46234 | G7: 600 | H7: 31 | I7: Completed
A8: CAM007 | B8: Export Market Campaign | C8: Website | D8: International | E8: 46204 | F8: 46265 | G8: 2000 | H8: 62 | I8: Completed
A9: CAM008 | B9: Customer Referral Campaign | C9: Referral | D9: Referral | E9: 46218 | F9: 46265 | G9: 700 | H9: 48 | I9: Completed
A10: CAM009 | B10: Organic Search Campaign | C10: Organic Search | D10: SEO | E10: 46174 | F10: 46265 | G10: 1000 | H10: 92 | I10: Completed
A11: CAM010 | B11: Instagram Product Campaign | C11: Instagram | D11: Social Media | E11: 46174 | F11: 46265 | G11: 1200 | H11: 92 | I11: Completed
A12: CAM011 | B12: Facebook Product Campaign | C12: Facebook | D12: Social Media | E12: 46174 | F12: 46265 | G12: 1100 | H12: 92 | I12: Completed
A13: CAM012 | B13: Phone Enquiry Campaign | C13: Phone | D13: Direct | E13: 46174 | F13: 46265 | G13: 300 | H13: 92 | I13: Completed

Sheet Opportunities
A1: Opportunity_ID | B1: Lead_ID | C1: Customer_ID | D1: Product_ID | E1: Product_Name | F1: Opportunity_Name | G1: Pipeline_Stage | H1: Amount | I1: Probability | J1: Expected_Value | K1: Expected_Close_Date | L1: Owner | M1: Lead_Date
A2: O0001 | B2: L0001 | C2: C0001 | D2: P001 | E2: EC580 | F2: EC580 Opportunity | G2: Negotiation | H2: 10000 | I2: 85 | J2: 8500 | K2: 46044 | L2: Sarah | M2: 46030
A3: O0005 | B3: L0005 | C3: C0005 | D3: P001 | E3: EC580 | F3: EC580 Opportunity | G3: New Lead | H3: 4000 | I3: 10 | J3: 400 | K3: 46280 | L3: David | M3: 46220
A4: O0002 | B4: L0002 | C4: C0002 | D4: P005 | E4: E850 | F4: E850 Opportunity | G4: Negotiation | H4: 10000 | I4: 85 | J4: 8500 | K4: 46151 | L4: David | M4: 46137
A5: O0003 | B5: L0003 | C5: C0003 | D5: P003 | E5: EC678 | F5: EC678 Opportunity | G5: Qualified | H5: 7000 | I5: 40 | J5: 2800 | K5: 46313 | L5: David | M5: 46268
A6: O0004 | B6: L0004 | C6: C0004 | D6: P003 | E6: EC678 | F6: EC678 Opportunity | G6: New Lead | H6: 4000 | I6: 10 | J6: 400 | K6: 46220 | L6: Emma | M6: 46160
A7: O0006 | B7: L0006 | C7: C0006 | D7: P003 | E7: EC678 | F7: EC678 Opportunity | G7: Qualified | H7: 7000 | I7: 40 | J7: 2800 | K7: 46158 | L7: James | M7: 46113
A8: O0007 | B8: L0007 | C8: C0007 | D8: P002 | E8: EC645 | F8: EC645 Opportunity | G8: Won | H8: 12000 | I8: 100 | J8: 12000 | K8: 46099 | L8: Emma | M8: 46092
A9: O0008 | B9: L0008 | C9: C0008 | D9: P003 | E9: EC678 | F9: EC678 Opportunity | G9: Negotiation | H9: 10000 | I9: 85 | J9: 8500 | K9: 46053 | L9: James | M9: 46039
A10: O0009 | B10: L0009 | C10: C0009 | D10: P002 | E10: EC645 | F10: EC645 Opportunity | G10: Site Survey | H10: 8000 | I10: 65 | J10: 5200 | K10: 46116 | L10: David | M10: 46086
A11: O0010 | B11: L0010 | C11: C0010 | D11: P003 | E11: EC678 | F11: EC678 Opportunity | G11: Information Pack Sent | H11: 6000 | I11: 50 | J11: 3000 | K11: 46193 | L11: David | M11: 46153
A12: O0011 | B12: L0011 | C12: C0011 | D12: P005 | E12: E850 | F12: E850 Opportunity | G12: Contacted | H12: 5000 | I12: 20 | J12: 1000 | K12: 46175 | L12: Emma | M12: 46120
A13: O0012 | B13: L0012 | C13: C0012 | D13: P003 | E13: EC678 | F13: EC678 Opportunity | G13: Proposal | H13: 9000 | I13: 75 | J13: 6750 | K13: 46119 | L13: Sarah | M13: 46098
... A19: O0018 | B19: L0018 | C19: C0018 | D19: P001 | E19: EC580 | F19: EC580 Opportunity | G19: Contacted | H19: 5000 | I19: 20 | J19: 1000 | K19: 46136 | L19: Sarah | M19: 46081
A20: O0019 | B20: L0019 | C20: C0019 | D20: P002 | E20: EC645 | F20: EC645 Opportunity | G20: Lost | H20: 0 | I20: 0 | J20: 0 | L20: David | M20: 46208
A21: O0020 | B21: L0020 | C21: C0020 | D21: P001 | E21: EC580 | F21: EC580 Opportunity | G21: Contacted | H21: 5000 | I21: 20 | J21: 1000 | K21: 46168 | L21: Emma | M21: 46113
A22: O0021 | B22: L0021 | C22: C0021 | D22: P004 | E22: EC730 | F22: EC730 Opportunity | G22: Proposal | H22: 9000 | I22: 75 | J22: 6750 | K22: 46107 | L22: Sarah | M22: 46086
A23: O0022 | B23: L0022 | C23: C0022 | D23: P004 | E23: EC730 | F23: EC730 Opportunity | G23: Information Pack Sent | H23: 6000 | I23: 50 | J23: 3000 | K23: 46176 | L23: Sarah | M23: 46136
A24: O0023 | B24: L0023 | C24: C0023 | D24: P002 | E24: EC645 | F24: EC645 Opportunity | G24: Negotiation | H24: 10000 | I24: 85 | J24: 8500 | K24: 46160 | L24: Emma | M24: 46146
A25: O0024 | B25: L0024 | C25: C0024 | D25: P004 | E25: EC730 | F25: EC730 Opportunity | G25: Site Survey | H25: 8000 | I25: 65 | J25: 5200 | K25: 46231 | L25: Emma | M25: 46201
A26: O0025 | B26: L0025 | C26: C0025 | D26: P005 | E26: E850 | F26: E850 Opportunity | G26: New Lead | H26: 4000 | I26: 10 | J26: 400 | K26: 46097 | L26: James | M26: 46037
A27: O0026 | B27: L0026 | C27: C0026 | D27: P005 | E27: E850 | F27: E850 Opportunity | G27: Contacted | H27: 5000 | I27: 20 | J27: 1000 | K27: 46095 | L27: David | M27: 46040
A28: O0027 | B28: L0027 | C28: C0027 | D28: P001 | E28: EC580 | F28: EC580 Opportunity | G28: Contacted | H28: 5000 | I28: 20 | J28: 1000 | K28: 46246 | L28: Emma | M28: 46191
A29: O0028 | B29: L0028 | C29: C0028 | D29: P003 | E29: EC678 | F29: EC678 Opportunity | G29: Negotiation | H29: 10000 | I29: 85 | J29: 8500 | K29: 46208 | L29: David | M29: 46194
A30: O0029 | B30: L0029 | C30: C0029 | D30: P005 | E30: E850 | F30: E850 Opportunity | G30: Contacted | H30: 5000 | I30: 20 | J30: 1000 | K30: 46215 | L30: Sarah | M30: 46160
A31: O0030 | B31: L0030 | C31: C0030 | D31: P003 | E31: EC678 | F31: EC678 Opportunity | G31: Qualified | H31: 7000 | I31: 40 | J31: 2800 | K31: 46281 | L31: Emma | M31: 46236
A32: O0031 | B32: L0031 | C32: C0031 | D32: P003 | E32: EC678 | F32: EC678 Opportunity | G32: Contacted | H32: 5000 | I32: 20 | J32: 1000 | K32: 46268 | L32: Sarah | M32: 46213
A33: O0032 | B33: L0032 | C33: C0032 | D33: P003 | E33: EC678 | F33: EC678 Opportunity | G33: Lost | H33: 0 | I33: 0 | J33: 0 | L33: Emma | M33: 46087
A34: O0033 | B34: L0033 | C34: C0033 | D34: P002 | E34: EC645 | F34: EC645 Opportunity | G34: Site Survey | H34: 8000 | I34: 65 | J34: 5200 | K34: 46242 | L34: David | M34: 46212
A35: O0034 | B35: L0034 | C35: C0034 | D35: P005 | E35: E850 | F35: E850 Opportunity | G35: New Lead | H35: 4000 | I35: 10 | J35: 400 | K35: 46232 | L35: James | M35: 46172
A36: O0035 | B36: L0035 | C36: C0035 | D36: P003 | E36: EC678 | F36: EC678 Opportunity | G36: Information Pack Sent | H36: 6000 | I36: 50 | J36: 3000 | K36: 46233 | L36: David | M36: 46193
A37: O0036 | B37: L0036 | C37: C0036 | D37: P002 | E37: EC645 | F37: EC645 Opportunity | G37: Negotiation | H37: 10000 | I37: 85 | J37: 8500 | K37: 46082 | L37: Sarah | M37: 46068
A38: O0037 | B38: L0037 | C38: C0037 | D38: P004 | E38: EC730 | F38: EC730 Opportunity | G38: Information Pack Sent | H38: 6000 | I38: 50 | J38: 3000 | K38: 46272 | L38: David | M38: 46232
A39: O0038 | B39: L0038 | C39: C0038 | D39: P002 | E39: EC645 | F39: EC645 Opportunity | G39: Negotiation | H39: 10000 | I39: 85 | J39: 8500 | K39: 46108 | L39: James | M39: 46094
A40: O0039 | B40: L0039 | C40: C0039 | D40: P001 | E40: EC580 | F40: EC580 Opportunity | G40: Contacted | H40: 5000 | I40: 20 | J40: 1000 | K40: 46123 | L40: James | M40: 46068
A41: O0040 | B41: L0040 | C41: C0040 | D41: P004 | E41: EC730 | F41: EC730 Opportunity | G41: Lost | H41: 0 | I41: 0 | J41: 0 | L41: Sarah | M41: 46121
A42: O0041 | B42: L0041 | C42: C0041 | D42: P005 | E42: E850 | F42: E850 Opportunity | G42: Information Pack Sent | H42: 6000 | I42: 50 | J42: 3000 | K42: 46173 | L42: James | M42: 46133
A43: O0042 | B43: L0042 | C43: C0042 | D43: P003 | E43: EC678 | F43: EC678 Opportunity | G43: Negotiation | H43: 10000 | I43: 85 | J43: 8500 | K43: 46140 | L43: James | M43: 46126
A44: O0043 | B44: L0043 | C44: C0043 | D44: P005 | E44: E850 | F44: E850 Opportunity | G44: Site Survey | H44: 8000 | I44: 65 | J44: 5200 | K44: 46193 | L44: Emma | M44: 46163
A45: O0044 | B45: L0044 | C45: C0044 | D45: P004 | E45: EC730 | F45: EC730 Opportunity | G45: Information Pack Sent | H45: 6000 | I45: 50 | J45: 3000 | K45: 46266 | L45: Emma | M45: 46226
...

Sheet Raw_Customer_Data
A1: Customer_ID | B1: First_Name | C1: Last_Name | D1: Country | E1: Customer_Type | F1: Email | G1: Phone | H1: Lead_Source | I1: Product_Interest | J1: Status | K1: Assigned_To | L1: Created_Date
A2: C0001 | B2: John | C2: Smith | D2: France | E2: Homeowner | F2: daniel.smith1@example.com | G2: +33 350 328 3286 | H2: Phone | I2: EC580 | J2: Negotiation | K2: Sarah | L2: 2026-01-08
A3: C0002 | B3: William | C3: Patel | D3: UK | E3: Commercial | F3: william.patel2@example.com | G3: +44 617 716 1434 | H3: Instagram | I3: E850 | J3: Negotiation | K3: David | L3: 2026-04-25
A4: C0003 | B4: Florence | C4: Wright | D4: United Kingdom | E4: Installer | F4: florence.wright3@example.com | G4: +44 877 925 3615 | H4: Referral | I4: EC678 | J4: Qualified | K4: David | L4: 2026-09-03
A5: C0004 | B5: Olivia | C5: Taylor | D5: UK | E5: Architect | F5: olivia.taylor4@example.com | G5: +44 489 199 6881 | H5: Organic Search | I5: EC678 | J5: New Lead | K5: Emma | L5: 2026-05-18
A6: C0005 | B6: Daniel | C6: Edwards | D6: UK | E6: Commercial | F6: daniel.edwards5@example.com | G6: +44 665 400 6925 | H6: Instagram | I6: EC580 | J6: New Lead | K6: David | L6: 2026-07-17
A7: C0006 | B7: Noah | C7: Wilson | D7: UK | E7: Architect | F7: noah.wilson6@example.com | G7: +44 987 203 7227 | H7: Email | I7: EC678 | J7: Qualified | K7: James | L7: 2026-04-01
A8: C0007 | B8: Jacob | C8: Wright | D8: UK | E8: Commercial | F8: jacob.wright7@example.com | G8: +44 723 750 3803 | H8: Instagram | I8: EC645 | J8: Won | K8: Emma | L8: 2026-03-11
A9: C0008 | B9: Charlotte | C9: Robinson | D9: France | E9: Dealer | G9: +33 963 886 1916 | H9: Website | I9: EC678 | J9: Negotiation | K9: James | L9: 2026-01-17
A10: C0009 | B10: Jacob | C10: Jackson | D10: France | E10: Installer | F10: jacob.jackson9@example.com | G10: +33 317 771 9179 | H10: Email | I10: EC645 | J10: Site Survey | K10: David | L10: 2026-03-05
A11: C0010 | B11: Charlotte | C11: Clarke | D11: UK | E11: Commercial | F11: charlotte.clarke10@example.com | G11: +44 864 698 8019 | H11: Dealer | I11: EC678 | J11: Information Pack Sent | K11: David | L11: 2026-05-11
A12: C0011 | B12: Lily | C12: Wilson | D12: UK | E12: Dealer | F12: lily.wilson11@example.com | G12: +44 981 212 3504 | H12: Dealer | I12: E850 | J12: Contacted | K12: Emma | L12: 2026-04-08
A13: C0012 | B13: Ruby | C13: Green | D13: Netherlands | E13: Homeowner | F13: ruby.green12@example.com | G13: +31 357 666 1188 | H13: Phone | I13: EC678 | J13: Proposal | K13: Sarah | L13: 2026-03-17
A14: C0013 | B14: Isabella | C14: Davies | D14: Ireland | E14: Commercial | F14: isabella.davies13@example.com | G14: +353 103 839 5315 | H14: Facebook | I14: E850 | J14: Contacted | K14: James | L14: 2026-08-04
A15: C0014 | B15: Freya | C15: Wood | D15: UK | E15: Commercial | F15: freya.wood14@example.com | G15: +44 256 482 3646 | H15: Phone | I15: EC580 | J15: Proposal | K15: Emma | L15: 2026-01-05
A16: C0015 | B16: Daniel | C16: White | D16: France | E16: Commercial | F16: daniel.white15@example.com | G16: +33 345 159 4946 | H16: Google | I16: EC580 | J16: Won | K16: Sarah | L16: 2026-09-08
A17: C0016 | B17: Alice | C17: Johnson | D17: UK | E17: Architect | F17: alice.johnson16@example.com | G17: +44 775 586 3705 | H17: Phone | I17: E850 | J17: Negotiation | K17: David | L17: 2026-08-26
A18: C0017 | B18: Alice | C18: Patel | D18: France | E18: Installer | F18: alice.patel17@example.com | G18: +33 508 787 7118 | H18: Phone | I18: EC730 | J18: Contacted | K18: David | L18: 2026-02-27
A19: C0018 | B19: Robert | C19: Walker | D19: UK | E19: Commercial | F19: robert.walker18@example.com | G19: +44 702 667 4770 | H19: Instagram | I19: EC580 | J19: Contacted | K19: Sarah | L19: 2026-02-28
A20: C0019 | B20: Robert | C20: Brown | D20: France | E20: Architect | F20: robert.brown19@example.com | G20: +33 172 626 4899 | H20: Email | I20: EC645 | J20: Lost | K20: David | L20: 2026-07-05
A21: C0020 | B21: Evie | C21: Jackson | D21: Spain | E21: Installer | F21: evie.jackson20@example.com | G21: +34 348 903 8749 | H21: Instagram | I21: EC580 | J21: Contacted | K21: Emma | L21: 2026-04-01
... A50: C0049 | B50: Freya | C50: Hughes | D50: Belgium | E50: Installer | F50: freya.hughes49@example.com | G50: +32 556 262 8777 | H50: Exhibition | I50: EC645 | J50: Site Survey | K50: Emma | L50: 2026-06-10
A51: C0050 | B51: Oscar | C51: Wright | D51: Ireland | E51: Dealer | F51: oscar.wright50@example.com | H51: Exhibition | I51: EC678 | J51: Proposal | K51: Sarah | L51: 2026-02-05
A52: C0051 | B52: George | C52: Robinson | D52: Germany | E52: Homeowner | F52: george.robinson51@example.com | G52: +49 810 256 4505 | H52: Dealer | I52: EC730 | J52: Proposal | K52: Emma | L52: 2026-04-17
A53: C0052 | B53: Michael | C53: Patel | D53: Ireland | E53: Commercial | F53: michael.patel52@example.com | G53: +353 498 888 1320 | H53: Dealer | I53: EC730 | J53: New Lead | K53: James | L53: 2026-03-18
A54: C0053 | B54: Sophia | C54: Hughes | D54: Netherlands | E54: Commercial | F54: sophia.hughes53@example.com | G54: +31 865 852 9947 | H54: Instagram | I54: EC730 | J54: Information Pack Sent | K54: James | L54: 2026-04-22
A55: C0054 | B55: Lily | C55: Smith | D55: Germany | E55: Dealer | F55: lily.smith54@example.com | G55: +49 444 784 7624 | H55: Email | I55: EC645 | J55: Lost | K55: Sarah | L55: 2026-08-21
A56: C0055 | B56: Isla | C56: Jackson | D56: Belgium | E56: Installer | F56: isla.jackson55@example.com | G56: +32 778 127 2375 | H56: Facebook | I56: EC730 | J56: Qualified | K56: Sarah | L56: 2026-03-08
A57: C0056 | B57: Sophia | C57: Walker | D57: UK | E57: Installer | F57: sophia.walker56@example.com | G57: +44 565 434 6529 | H57: Exhibition | I57: EC730 | J57: Site Survey | K57: Sarah | L57: 2026-05-01
A58: C0057 | B58: James | C58: Clarke | D58: UK | E58: Homeowner | F58: james.clarke57@example.com | G58: +44 458 329 2124 | H58: Website | I58: EC645 | J58: Information Pack Sent | K58: Sarah | L58: 2026-06-09
A59: C0058 | B59: George | C59: Robinson | D59: UK | E59: Commercial | F59: george.robinson58@example.com | G59: +44 584 785 2874 | H59: Instagram | I59: EC730 | J59: Site Survey | K59: James | L59: 2026-02-12
A60: C0059 | B60: Ruby | C60: Wood | D60: UK | E60: Architect | F60: ruby.wood59@example.com | G60: +44 896 938 3683 | H60: Google | I60: E850 | J60: New Lead | K60: James | L60: 2026-05-28
A61: C0060 | B61: Sophia | C61: Edwards | D61: UK | E61: Homeowner | F61: sophia.edwards60@example.com | G61: +44 177 706 4978 | H61: Exhibition | I61: E850 | J61: Contacted | K61: Sarah | L61: 2026-03-30
A62: C0061 | B62: Alice | C62: Hughes | D62: Germany | E62: Homeowner | F62: alice.hughes61@example.com | G62: +49 170 618 6590 | H62: Dealer | I62: EC730 | J62: Contacted | K62: Emma | L62: 2026-09-03
A63: C0062 | B63: Emily | C63: Green | D63: UK | E63: Architect | F63: emily.green62@example.com | G63: +44 545 280 9548 | H63: Organic Search | I63: E850 | J63: Won | K63: Emma | L63: 2026-04-22
... A119: C0118 | B119: Olivia | C119: Green | D119: Germany | E119: Architect | F119: olivia.green118@example.com | G119: +49 525 847 2557 | H119: Dealer | I119: EC678 | J119: Site Survey | K119: James | L119: 2026-09-02
A120: C0119 | C120: Hall | D120: UK | E120: Homeowner | F120: george.hall119@example.com | G120: +44 193 951 2398 | H120: Dealer | I120: EC580 | J120: Proposal | K120: David | L120: 2026-05-23
A121: C0120 | B121: Michael | C121: Jackson | D121: Belgium | E121: Installer | F121: michael.jackson120@example.com | G121: +32 675 437 3002 | H121: Referral | I121: EC730 | J121: New Lead | K121: James | L121: 2026-06-03
A122: C0121 | B122: Theo | C122: White | D122: UK | E122: Dealer | F122: theo.white121@example.com | G122: +44 691 619 4485 | H122: Email | I122: EC645 | J122: Contacted | K122: James | L122: 2026-08-05
A123: C0122 | B123: Charlotte | C123: White | D123: UK | E123: Installer | F123: charlotte.white122@example.com | G123: +44 880 385 4705 | H123: Phone | I123: E850 | J123: Lost | K123: Sarah | L123: 2026-06-05
...

Sheet Data_Dictionary
A1: Field | B1: Purpose | C1: CRM Use | D1: Example
A2: Customer_ID | B2: Unique identifier for each customer | C2: Primary Key | D2: C0001...C0150
A3: First_Name | B3: Customer first name | C3: Customer information | D3: John
A4: Last_Name | B4: Customer surname | C4: Customer information | D4: Smith
A5: Country | B5: Customer country/market | C5: Segmentation & export analysis | D5: UK
A6: Customer_Type | B6: Relationship type | C6: Segmentation | D6: Homeowner / Dealer / Architect / Installer / Commercial
A7: Email | B7: Main customer email | C7: Communication | D7: example@email.com
A8: Phone | B8: Main customer phone | C8: Communication | D8: +44...
A9: Lead_Source | B9: How the customer/lead was acquired | C9: Marketing attribution | D9: Website / Exhibition / Referral
A10: Product_Interest | B10: Product currently of interest | C10: Sales & product analysis | D10: EC678
A11: Status | B11: Current CRM/sales stage | C11: Pipeline management | D11: Qualified / Proposal / Won
A12: Assigned_To | B12: Responsible sales team member | C12: Ownership & follow-up | D12: Sarah
A13: Created_Date | B13: Date record entered | C13: Time-based analysis | D13: 2026-05-12

Sheet Sales_Pipeline
A1: Stage_ID | B1: Stage_Name | C1: Stage_Weight | D1: Definition
A2: S01 | B2: New Lead | C2: 10 | D2: New enquiry received
A3: S02 | B3: Contacted | C3: 20 | D3: First contact completed
A4: S03 | B4: Qualified | C4: 35 | D4: Lead meets basic qualification criteria
A5: S04 | B5: Information Pack Sent | C5: 45 | D5: Customer requested/received information
A6: S05 | B6: Site Survey | C6: 60 | D6: Site survey arranged/completed
A7: S06 | B7: Proposal | C7: 75 | D7: Quotation/proposal issued
A8: S07 | B8: Negotiation | C8: 85 | D8: Commercial discussion ongoing
A9: S08 | B9: Won | C9: 100 | D9: Customer converted
A10: S09 | B10: Lost | C10: 0 | D10: Opportunity closed without conversion

Sheet CRM_Relationships
A1: Parent_Table | B1: Parent_Key | C1: Child_Table | D1: Child_Key | E1: Relationship
A2: Customers | B2: Customer_ID | C2: Leads | D2: Customer_ID | E2: One customer can have multiple leads/interactions
A3: Products | B3: Product_ID | C3: Leads | D3: Product_ID | E3: A lead can be associated with a product
A4: Pipeline | B4: Stage_ID | C4: Leads | D4: Stage_ID | E4: Each lead has one current sales stage
A5: Customers | B5: Customer_ID | C5: Activities | D5: Customer_ID | E5: A customer can have multiple activities
